[2022-11-27T09:54:49.549+0000] {taskinstance.py:1165} INFO - Dependencies all met for <TaskInstance: user_processing.process_user manual__2022-11-27T09:54:20.233021+00:00 [queued]>
[2022-11-27T09:54:49.623+0000] {taskinstance.py:1165} INFO - Dependencies all met for <TaskInstance: user_processing.process_user manual__2022-11-27T09:54:20.233021+00:00 [queued]>
[2022-11-27T09:54:49.626+0000] {taskinstance.py:1362} INFO - 
--------------------------------------------------------------------------------
[2022-11-27T09:54:49.627+0000] {taskinstance.py:1363} INFO - Starting attempt 1 of 1
[2022-11-27T09:54:49.630+0000] {taskinstance.py:1364} INFO - 
--------------------------------------------------------------------------------
[2022-11-27T09:54:49.686+0000] {taskinstance.py:1383} INFO - Executing <Task(PythonOperator): process_user> on 2022-11-27 09:54:20.233021+00:00
[2022-11-27T09:54:49.706+0000] {standard_task_runner.py:55} INFO - Started process 5164 to run task
[2022-11-27T09:54:49.733+0000] {standard_task_runner.py:82} INFO - Running: ['***', 'tasks', 'run', 'user_processing', 'process_user', 'manual__2022-11-27T09:54:20.233021+00:00', '--job-id', '28', '--raw', '--subdir', 'DAGS_FOLDER/user_processing.py', '--cfg-path', '/tmp/tmp19vssfu9']
[2022-11-27T09:54:49.742+0000] {standard_task_runner.py:83} INFO - Job 28: Subtask process_user
[2022-11-27T09:54:49.961+0000] {task_command.py:376} INFO - Running <TaskInstance: user_processing.process_user manual__2022-11-27T09:54:20.233021+00:00 [running]> on host c7f7231a8603
[2022-11-27T09:54:50.253+0000] {taskinstance.py:1592} INFO - Exporting the following env vars:
AIRFLOW_CTX_DAG_OWNER=***
AIRFLOW_CTX_DAG_ID=user_processing
AIRFLOW_CTX_TASK_ID=process_user
AIRFLOW_CTX_EXECUTION_DATE=2022-11-27T09:54:20.233021+00:00
AIRFLOW_CTX_TRY_NUMBER=1
AIRFLOW_CTX_DAG_RUN_ID=manual__2022-11-27T09:54:20.233021+00:00
[2022-11-27T09:54:50.461+0000] {taskinstance.py:1851} ERROR - Task failed with exception
Traceback (most recent call last):
  File "/home/airflow/.local/lib/python3.7/site-packages/airflow/operators/python.py", line 175, in execute
    return_value = self.execute_callable()
  File "/home/airflow/.local/lib/python3.7/site-packages/airflow/operators/python.py", line 193, in execute_callable
    return self.python_callable(*self.op_args, **self.op_kwargs)
  File "/opt/airflow/dags/user_processing.py", line 22, in _process_user
    process_user.to_csv('tmp/process_user.csv', index=None, header=False)
  File "/home/airflow/.local/lib/python3.7/site-packages/pandas/core/generic.py", line 3482, in to_csv
    storage_options=storage_options,
  File "/home/airflow/.local/lib/python3.7/site-packages/pandas/io/formats/format.py", line 1105, in to_csv
    csv_formatter.save()
  File "/home/airflow/.local/lib/python3.7/site-packages/pandas/io/formats/csvs.py", line 243, in save
    storage_options=self.storage_options,
  File "/home/airflow/.local/lib/python3.7/site-packages/pandas/io/common.py", line 707, in get_handle
    newline="",
FileNotFoundError: [Errno 2] No such file or directory: 'tmp/process_user.csv'
[2022-11-27T09:54:50.524+0000] {taskinstance.py:1406} INFO - Marking task as FAILED. dag_id=user_processing, task_id=process_user, execution_date=20221127T095420, start_date=20221127T095449, end_date=20221127T095450
[2022-11-27T09:54:50.608+0000] {standard_task_runner.py:105} ERROR - Failed to execute job 28 for task process_user ([Errno 2] No such file or directory: 'tmp/process_user.csv'; 5164)
[2022-11-27T09:54:50.720+0000] {local_task_job.py:164} INFO - Task exited with return code 1
[2022-11-27T09:54:50.892+0000] {local_task_job.py:273} INFO - 0 downstream tasks scheduled from follow-on schedule check
