[2022-11-27T09:44:15.469+0000] {taskinstance.py:1165} INFO - Dependencies all met for <TaskInstance: user_processing.process_user manual__2022-11-27T09:43:59.762536+00:00 [queued]>
[2022-11-27T09:44:15.485+0000] {taskinstance.py:1165} INFO - Dependencies all met for <TaskInstance: user_processing.process_user manual__2022-11-27T09:43:59.762536+00:00 [queued]>
[2022-11-27T09:44:15.487+0000] {taskinstance.py:1362} INFO - 
--------------------------------------------------------------------------------
[2022-11-27T09:44:15.489+0000] {taskinstance.py:1363} INFO - Starting attempt 1 of 1
[2022-11-27T09:44:15.491+0000] {taskinstance.py:1364} INFO - 
--------------------------------------------------------------------------------
[2022-11-27T09:44:15.522+0000] {taskinstance.py:1383} INFO - Executing <Task(PythonOperator): process_user> on 2022-11-27 09:43:59.762536+00:00
[2022-11-27T09:44:15.538+0000] {standard_task_runner.py:55} INFO - Started process 4711 to run task
[2022-11-27T09:44:15.550+0000] {standard_task_runner.py:82} INFO - Running: ['***', 'tasks', 'run', 'user_processing', 'process_user', 'manual__2022-11-27T09:43:59.762536+00:00', '--job-id', '16', '--raw', '--subdir', 'DAGS_FOLDER/user_processing.py', '--cfg-path', '/tmp/tmpjkdv6s8p']
[2022-11-27T09:44:15.557+0000] {standard_task_runner.py:83} INFO - Job 16: Subtask process_user
[2022-11-27T09:44:15.676+0000] {task_command.py:376} INFO - Running <TaskInstance: user_processing.process_user manual__2022-11-27T09:43:59.762536+00:00 [running]> on host c7f7231a8603
[2022-11-27T09:44:15.772+0000] {taskinstance.py:1592} INFO - Exporting the following env vars:
AIRFLOW_CTX_DAG_OWNER=***
AIRFLOW_CTX_DAG_ID=user_processing
AIRFLOW_CTX_TASK_ID=process_user
AIRFLOW_CTX_EXECUTION_DATE=2022-11-27T09:43:59.762536+00:00
AIRFLOW_CTX_TRY_NUMBER=1
AIRFLOW_CTX_DAG_RUN_ID=manual__2022-11-27T09:43:59.762536+00:00
[2022-11-27T09:44:15.806+0000] {taskinstance.py:1851} ERROR - Task failed with exception
Traceback (most recent call last):
  File "/home/airflow/.local/lib/python3.7/site-packages/airflow/operators/python.py", line 175, in execute
    return_value = self.execute_callable()
  File "/home/airflow/.local/lib/python3.7/site-packages/airflow/operators/python.py", line 193, in execute_callable
    return self.python_callable(*self.op_args, **self.op_kwargs)
  File "/opt/airflow/dags/user_processing.py", line 13, in _process_user
    user = user['result'][0]
KeyError: 'result'
[2022-11-27T09:44:15.829+0000] {taskinstance.py:1406} INFO - Marking task as FAILED. dag_id=user_processing, task_id=process_user, execution_date=20221127T094359, start_date=20221127T094415, end_date=20221127T094415
[2022-11-27T09:44:15.892+0000] {standard_task_runner.py:105} ERROR - Failed to execute job 16 for task process_user ('result'; 4711)
[2022-11-27T09:44:15.930+0000] {local_task_job.py:164} INFO - Task exited with return code 1
[2022-11-27T09:44:16.020+0000] {local_task_job.py:273} INFO - 0 downstream tasks scheduled from follow-on schedule check
