[2023-01-16T01:55:57.662+0000] {taskinstance.py:1165} INFO - Dependencies all met for <TaskInstance: user_processing.create_table scheduled__2023-01-13T00:00:00+00:00 [queued]>
[2023-01-16T01:55:57.744+0000] {taskinstance.py:1165} INFO - Dependencies all met for <TaskInstance: user_processing.create_table scheduled__2023-01-13T00:00:00+00:00 [queued]>
[2023-01-16T01:55:57.750+0000] {taskinstance.py:1362} INFO - 
--------------------------------------------------------------------------------
[2023-01-16T01:55:57.756+0000] {taskinstance.py:1363} INFO - Starting attempt 1 of 1
[2023-01-16T01:55:57.757+0000] {taskinstance.py:1364} INFO - 
--------------------------------------------------------------------------------
[2023-01-16T01:55:57.907+0000] {taskinstance.py:1383} INFO - Executing <Task(PostgresOperator): create_table> on 2023-01-13 00:00:00+00:00
[2023-01-16T01:55:57.960+0000] {standard_task_runner.py:55} INFO - Started process 8324 to run task
[2023-01-16T01:55:58.028+0000] {standard_task_runner.py:82} INFO - Running: ['***', 'tasks', 'run', 'user_processing', 'create_table', 'scheduled__2023-01-13T00:00:00+00:00', '--job-id', '29', '--raw', '--subdir', 'DAGS_FOLDER/user_processing.py', '--cfg-path', '/tmp/tmp10y2fqj7']
[2023-01-16T01:55:58.064+0000] {standard_task_runner.py:83} INFO - Job 29: Subtask create_table
[2023-01-16T01:55:58.064+0000] {taskinstance.py:1159} INFO - Dependencies not met for <TaskInstance: user_processing.create_table scheduled__2023-01-13T00:00:00+00:00 [running]>, dependency 'Task Instance Not Running' FAILED: Task is in the running state
[2023-01-16T01:55:58.068+0000] {taskinstance.py:1159} INFO - Dependencies not met for <TaskInstance: user_processing.create_table scheduled__2023-01-13T00:00:00+00:00 [running]>, dependency 'Task Instance State' FAILED: Task is in the 'running' state.
[2023-01-16T01:55:58.130+0000] {local_task_job.py:103} INFO - Task is not able to be run
[2023-01-16T01:55:58.587+0000] {task_command.py:376} INFO - Running <TaskInstance: user_processing.create_table scheduled__2023-01-13T00:00:00+00:00 [running]> on host e4c135bf00be
[2023-01-16T01:55:59.107+0000] {taskinstance.py:1592} INFO - Exporting the following env vars:
AIRFLOW_CTX_DAG_OWNER=***
AIRFLOW_CTX_DAG_ID=user_processing
AIRFLOW_CTX_TASK_ID=create_table
AIRFLOW_CTX_EXECUTION_DATE=2023-01-13T00:00:00+00:00
AIRFLOW_CTX_TRY_NUMBER=1
AIRFLOW_CTX_DAG_RUN_ID=scheduled__2023-01-13T00:00:00+00:00
[2023-01-16T01:55:59.193+0000] {taskinstance.py:1851} ERROR - Task failed with exception
Traceback (most recent call last):
  File "/home/airflow/.local/lib/python3.7/site-packages/airflow/providers/postgres/operators/postgres.py", line 94, in execute
    self.hook.run(self.sql, self.autocommit, parameters=self.parameters)
  File "/home/airflow/.local/lib/python3.7/site-packages/airflow/providers/common/sql/hooks/sql.py", line 288, in run
    with closing(self.get_conn()) as conn:
  File "/home/airflow/.local/lib/python3.7/site-packages/airflow/providers/postgres/hooks/postgres.py", line 88, in get_conn
    conn = deepcopy(self.connection or self.get_connection(conn_id))
  File "/home/airflow/.local/lib/python3.7/site-packages/airflow/hooks/base.py", line 70, in get_connection
    conn = Connection.get_connection_from_secrets(conn_id)
  File "/home/airflow/.local/lib/python3.7/site-packages/airflow/models/connection.py", line 432, in get_connection_from_secrets
    raise AirflowNotFoundException(f"The conn_id `{conn_id}` isn't defined")
airflow.exceptions.AirflowNotFoundException: The conn_id `postgres` isn't defined
[2023-01-16T01:55:59.227+0000] {taskinstance.py:1406} INFO - Marking task as FAILED. dag_id=user_processing, task_id=create_table, execution_date=20230113T000000, start_date=20230116T015557, end_date=20230116T015559
[2023-01-16T01:55:59.333+0000] {standard_task_runner.py:105} ERROR - Failed to execute job 29 for task create_table (The conn_id `postgres` isn't defined; 8324)
[2023-01-16T01:55:59.415+0000] {local_task_job.py:164} INFO - Task exited with return code 1
[2023-01-16T01:55:59.778+0000] {local_task_job.py:273} INFO - 0 downstream tasks scheduled from follow-on schedule check
