[2022-11-27T09:48:41.872+0000] {taskinstance.py:1165} INFO - Dependencies all met for <TaskInstance: user_processing.process_user manual__2022-11-27T09:48:29.416483+00:00 [queued]>
[2022-11-27T09:48:41.883+0000] {taskinstance.py:1165} INFO - Dependencies all met for <TaskInstance: user_processing.process_user manual__2022-11-27T09:48:29.416483+00:00 [queued]>
[2022-11-27T09:48:41.885+0000] {taskinstance.py:1362} INFO - 
--------------------------------------------------------------------------------
[2022-11-27T09:48:41.886+0000] {taskinstance.py:1363} INFO - Starting attempt 1 of 1
[2022-11-27T09:48:41.887+0000] {taskinstance.py:1364} INFO - 
--------------------------------------------------------------------------------
[2022-11-27T09:48:41.900+0000] {taskinstance.py:1383} INFO - Executing <Task(PythonOperator): process_user> on 2022-11-27 09:48:29.416483+00:00
[2022-11-27T09:48:41.915+0000] {standard_task_runner.py:55} INFO - Started process 4897 to run task
[2022-11-27T09:48:41.926+0000] {standard_task_runner.py:82} INFO - Running: ['***', 'tasks', 'run', 'user_processing', 'process_user', 'manual__2022-11-27T09:48:29.416483+00:00', '--job-id', '20', '--raw', '--subdir', 'DAGS_FOLDER/user_processing.py', '--cfg-path', '/tmp/tmp0k4jrbt_']
[2022-11-27T09:48:41.933+0000] {standard_task_runner.py:83} INFO - Job 20: Subtask process_user
[2022-11-27T09:48:42.036+0000] {task_command.py:376} INFO - Running <TaskInstance: user_processing.process_user manual__2022-11-27T09:48:29.416483+00:00 [running]> on host c7f7231a8603
[2022-11-27T09:48:42.159+0000] {taskinstance.py:1592} INFO - Exporting the following env vars:
AIRFLOW_CTX_DAG_OWNER=***
AIRFLOW_CTX_DAG_ID=user_processing
AIRFLOW_CTX_TASK_ID=process_user
AIRFLOW_CTX_EXECUTION_DATE=2022-11-27T09:48:29.416483+00:00
AIRFLOW_CTX_TRY_NUMBER=1
AIRFLOW_CTX_DAG_RUN_ID=manual__2022-11-27T09:48:29.416483+00:00
[2022-11-27T09:48:42.188+0000] {taskinstance.py:1851} ERROR - Task failed with exception
Traceback (most recent call last):
  File "/home/airflow/.local/lib/python3.7/site-packages/airflow/operators/python.py", line 175, in execute
    return_value = self.execute_callable()
  File "/home/airflow/.local/lib/python3.7/site-packages/airflow/operators/python.py", line 193, in execute_callable
    return self.python_callable(*self.op_args, **self.op_kwargs)
  File "/opt/airflow/dags/user_processing.py", line 17, in _process_user
    'country': user['name']['country'],
KeyError: 'country'
[2022-11-27T09:48:42.205+0000] {taskinstance.py:1406} INFO - Marking task as FAILED. dag_id=user_processing, task_id=process_user, execution_date=20221127T094829, start_date=20221127T094841, end_date=20221127T094842
[2022-11-27T09:48:42.222+0000] {standard_task_runner.py:105} ERROR - Failed to execute job 20 for task process_user ('country'; 4897)
[2022-11-27T09:48:42.260+0000] {local_task_job.py:164} INFO - Task exited with return code 1
[2022-11-27T09:48:42.319+0000] {local_task_job.py:273} INFO - 0 downstream tasks scheduled from follow-on schedule check
